<?xml version="1.0" encoding="UTF-8"?>
<!-- Generated by org.testng.reporters.JUnitReportReporter -->
<testsuite hostname="KareemYasser" failures="1" tests="3" name="baimsLogin.Twitter_Login" time="175.452" errors="0" timestamp="2022-05-17T12:15:50 EET" skipped="0">
  <testcase classname="baimsLogin.Twitter_Login" name="ValidTwitter" time="70.792">
    <failure message="expected:&lt;https://auth.baims.com/ar&gt; but was:&lt;https://baims.com/&gt;" type="java.lang.AssertionError">
      <![CDATA[java.lang.AssertionError: expected:<https://auth.baims.com/ar> but was:<https://baims.com/>
at org.testng.AssertJUnit.assertEquals(AssertJUnit.java:115)
at org.testng.AssertJUnit.assertEquals(AssertJUnit.java:125)
at baimsLogin.Twitter_Login.ValidTwitter(Twitter_Login.java:33)
at java.base/jdk.internal.reflect.DirectMethodHandleAccessor.invoke(DirectMethodHandleAccessor.java:104)
at java.base/java.lang.reflect.Method.invoke(Method.java:577)
at org.testng.internal.invokers.MethodInvocationHelper.invokeMethod(MethodInvocationHelper.java:135)
at org.testng.internal.invokers.TestInvoker.invokeMethod(TestInvoker.java:673)
at org.testng.internal.invokers.TestInvoker.invokeTestMethod(TestInvoker.java:220)
at org.testng.internal.invokers.MethodRunner.runInSequence(MethodRunner.java:50)
at org.testng.internal.invokers.TestInvoker$MethodInvocationAgent.invoke(TestInvoker.java:945)
at org.testng.internal.invokers.TestInvoker.invokeTestMethods(TestInvoker.java:193)
at org.testng.internal.invokers.TestMethodWorker.invokeTestMethods(TestMethodWorker.java:146)
at org.testng.internal.invokers.TestMethodWorker.run(TestMethodWorker.java:128)
at java.base/java.util.ArrayList.forEach(ArrayList.java:1511)
at org.testng.TestRunner.privateRun(TestRunner.java:808)
at org.testng.TestRunner.run(TestRunner.java:603)
at org.testng.SuiteRunner.runTest(SuiteRunner.java:429)
at org.testng.SuiteRunner.runSequentially(SuiteRunner.java:423)
at org.testng.SuiteRunner.privateRun(SuiteRunner.java:383)
at org.testng.SuiteRunner.run(SuiteRunner.java:326)
at org.testng.SuiteRunnerWorker.runSuite(SuiteRunnerWorker.java:52)
at org.testng.SuiteRunnerWorker.run(SuiteRunnerWorker.java:95)
at org.testng.TestNG.runSuitesSequentially(TestNG.java:1249)
at org.testng.TestNG.runSuitesLocally(TestNG.java:1169)
at org.testng.TestNG.runSuites(TestNG.java:1092)
at org.testng.TestNG.run(TestNG.java:1060)
at org.testng.remote.AbstractRemoteTestNG.run(AbstractRemoteTestNG.java:115)
at org.testng.remote.RemoteTestNG.initAndRun(RemoteTestNG.java:251)
at org.testng.remote.RemoteTestNG.main(RemoteTestNG.java:77)
]]>
    </failure>
  </testcase> <!-- ValidTwitter -->
  <system-out/>
  <testcase classname="baimsLogin.Twitter_Login" name="InvalidTMmail" time="41.524"/>
  <system-out/>
  <testcase classname="baimsLogin.Twitter_Login" name="InvalidTPassword" time="63.136"/>
  <system-out/>
</testsuite> <!-- baimsLogin.Twitter_Login -->
